Workbook

Sheet NRI_Louisiana
A1: STATEABBRV | B1: COUNTY | C1: POPULATION | D1: BUILDVALUE | E1: RISK_SCORE | F1: RISK_RATNG | G1: EAL_SCORE | H1: EAL_VALT | I1: CFLD_EALT | J1: HRCN_EALT | K1: IFLD_EALT
A2: LA | B2: Acadia | C2: 57475 | D2: 12146909074 | E2: 88.613232 | F2: Relatively Moderate | G2: 83.972772 | H2: 50669160 | I2: 33011.113 | J2: 21908089 | K2: 19080498
A3: LA | B3: Allen | C3: 22708 | D3: 4379047454 | E3: 50.699746 | F3: Relatively Low | G3: 48.050743 | H3: 13966087 | I3: 4452.0293 | J3: 3190902.9 | K3: 4828706.7
A4: LA | B4: Ascension | C4: 126426 | D4: 33891912888 | E4: 92.143766 | F4: Relatively Moderate | G4: 92.357673 | H4: 1.2005973e+08 | I4: 2170874.3 | J4: 74181524 | K4: 18498958
A5: LA | B5: Assumption | C5: 21017 | D5: 3694550028 | E5: 70.292621 | F5: Relatively Low | G5: 60.860149 | H5: 20205198 | I5: 1348849.8 | J5: 10724194 | K5: 2424312.8
A6: LA | B6: Avoyelles | C6: 39654 | D6: 7263081772 | E6: 72.996183 | F6: Relatively Low | G6: 60.055693 | H6: 19898381 | I6: 0 | J6: 4775662.5 | K6: 3539154.9
A7: LA | B7: Beauregard | C7: 36508 | D7: 7276727176 | E7: 55.566158 | F7: Relatively Low | G7: 54.300743 | H7: 16616742 | I7: 736.59818 | J7: 2464017.9 | K7: 8049386.9
A8: LA | B8: Bienville | C8: 12958 | D8: 2655204791 | E8: 28.657761 | F8: Very Low | G8: 15.872525 | H8: 5665212.7 | J8: 294435.83 | K8: 1780836.2
A9: LA | B9: Bossier | C9: 128536 | D9: 20907296495 | E9: 82.538168 | F9: Relatively Moderate | G9: 82.79703 | H9: 47520655 | J9: 935317.76 | K9: 15072079
A10: LA | B10: Caddo | C10: 237695 | D10: 48091984659 | E10: 92.620865 | F10: Relatively Moderate | G10: 89.634901 | H10: 88791127 | J10: 2105136.8 | K10: 34661559
A11: LA | B11: Calcasieu | C11: 216652 | D11: 47460909111 | E11: 95.706107 | F11: Relatively High | G11: 94.709158 | H11: 1.6356362e+08 | I11: 2894382.7 | J11: 71000061 | K11: 58463563
A12: LA | B12: Caldwell | C12: 9627 | D12: 1785823142 | E12: 10.496183 | F12: Very Low | G12: 7.9826733 | H12: 3948529.5 | J12: 208116.25 | K12: 1703210
A13: LA | B13: Cameron | C13: 5615 | D13: 1244816286 | E13: 33.651399 | F13: Very Low | G13: 37.035891 | H13: 10565249 | I13: 3578894.2 | J13: 2534130.4 | K13: 841309.19
A14: LA | B14: Catahoula | C14: 8891 | D14: 1697326913 | E14: 17.016539 | F14: Very Low | G14: 8.1683168 | H14: 4000047.8 | J14: 524798.54 | K14: 1081335.8
A15: LA | B15: Claiborne | C15: 14160 | D15: 2852271897 | E15: 41.73028 | F15: Very Low | G15: 23.391089 | H15: 7311091.9 | J15: 315603.92 | K15: 2314222.4
A16: LA | B16: Concordia | C16: 18648 | D16: 3740198463 | E16: 31.552163 | F16: Very Low | G16: 20.761139 | H16: 6763904.3 | I16: 0 | J16: 906612.46 | K16: 1791096.6
A17: LA | B17: De Soto | C17: 26713 | D17: 4661706100 | E17: 42.016539 | F17: Very Low | G17: 31.373762 | H17: 9090062.7 | J17: 318336.38 | K17: 4094465.9
A18: LA | B18: East Baton Rouge | C18: 456512 | D18: 125800226187 | E18: 97.964377 | F18: Relatively High | G18: 97.091584 | H18: 2.6658784e+08 | I18: 240077.32 | J18: 67157192 | K18: 1.0322136e+08
A19: LA | B19: East Carroll | C19: 7455 | D19: 1340858266 | E19: 21.596692 | F19: Very Low | G19: 11.107673 | H19: 4548690.8 | J19: 259063.81 | K19: 698876.58
A20: LA | B20: East Feliciana | C20: 19513 | D20: 5168950969 | E20: 56.424936 | F20: Relatively Low | G20: 44.678218 | H20: 12748143 | I20: 0 | J20: 2376753.6 | K20: 5149612
A21: LA | B21: Evangeline | C21: 32319 | D21: 5562696492 | E21: 75.922392 | F21: Relatively Low | G21: 65.222772 | H21: 22945787 | I21: 0 | J21: 4593068 | K21: 6305353.5
A22: LA | B22: Franklin | C22: 19763 | D22: 3550288697 | E22: 35.909669 | F22: Very Low | G22: 25.433168 | H22: 7752047.7 | J22: 552211.48 | K22: 2437450.7
A23: LA | B23: Grant | C23: 22122 | D23: 3468887601 | E23: 29.611959 | F23: Very Low | G23: 27.784653 | H23: 8315304.7 | J23: 309232.72 | K23: 4213359
A24: LA | B24: Iberia | C24: 69859 | D24: 12074287106 | E24: 90.617048 | F24: Relatively Moderate | G24: 86.850248 | H24: 63756061 | I24: 917629.99 | J24: 33448403 | K24: 15036529
A25: LA | B25: Iberville | C25: 30214 | D25: 6469473899 | E25: 73.727735 | F25: Relatively Low | G25: 69.523515 | H25: 26822072 | I25: 664129.87 | J25: 14985838 | K25: 3548611.8
A26: LA | B26: Jackson | C26: 15021 | D26: 3311146855 | E26: 26.176845 | F26: Very Low | G26: 15.686881 | H26: 5645011.8 | J26: 235520.66 | K26: 2080990.7
A27: LA | B27: Jefferson | C27: 440590 | D27: 73299241386 | E27: 98.664122 | F27: Relatively High | G27: 98.45297 | H27: 3.7087641e+08 | I27: 10799982 | J27: 2.5067797e+08 | K27: 75821880
A28: LA | B28: Jefferson Davis | C28: 32235 | D28: 6396665106 | E28: 74.332061 | F28: Relatively Low | G28: 70.575495 | H28: 27745066 | I28: 42615.827 | J28: 10363292 | K28: 9670607.5
A29: LA | B29: Lafayette | C29: 241618 | D29: 50641403221 | E29: 95.165394 | F29: Relatively High | G29: 95.420792 | H29: 1.8984492e+08 | I29: 51220.28 | J29: 97824351 | K29: 57387452
A30: LA | B30: Lafourche | C30: 97393 | D30: 14412732933 | E30: 91.348601 | F30: Relatively Moderate | G30: 89.170792 | H30: 82742865 | I30: 2121187.9 | J30: 53744499 | K30: 8604666.5
A31: LA | B31: LaSalle | C31: 14762 | D31: 2432968049 | E31: 12.150127 | F31: Very Low | G31: 13.056931 | H31: 4982414.8 | J31: 333752.07 | K31: 2578496.6
A32: LA | B32: Lincoln | C32: 48370 | D32: 8988135137 | E32: 64.344784 | F32: Relatively Low | G32: 54.393564 | H32: 16672142 | J32: 307660.88 | K32: 5242490.7
A33: LA | B33: Livingston | C33: 142163 | D33: 29388047281 | E33: 94.465649 | F33: Relatively High | G33: 94.80198 | H33: 1.6562781e+08 | I33: 2223284.5 | J33: 61754611 | K33: 75528998
A34: LA | B34: Madison | C34: 10010 | D34: 1826004429 | E34: 32.442748 | F34: Very Low | G34: 18.502475 | H34: 6206483.2 | J34: 336886.96 | K34: 1294767.2
A35: LA | B35: Morehouse | C35: 25583 | D35: 5549657685 | E35: 55.279898 | F35: Relatively Low | G35: 39.727723 | H35: 11226512 | J35: 310087.25 | K35: 5426064.8
A36: LA | B36: Natchitoches | C36: 37330 | D36: 8549461697 | E36: 56.39313 | F36: Relatively Low | G36: 46.720297 | H36: 13483599 | J36: 706072.22 | K36: 6729719.6
A37: LA | B37: Orleans | C37: 383606 | D37: 65275492153 | E37: 98.250636 | F37: Relatively High | G37: 97.803218 | H37: 3.0407027e+08 | I37: 1856223.3 | J37: 2.2294861e+08 | K37: 46671982
A38: LA | B38: Ouachita | C38: 160298 | D38: 31950100490 | E38: 87.5 | F38: Relatively Moderate | G38: 83.84901 | H38: 50274042 | J38: 1319574.9 | K38: 21733983
A39: LA | B39: Plaquemines | C39: 23448 | D39: 5467152903 | E39: 72.93257 | F39: Relatively Low | G39: 70.82302 | H39: 28104734 | I39: 2799811.4 | J39: 19105260 | K39: 2738189.7
A40: LA | B40: Pointe Coupee | C40: 20697 | D40: 5248159269 | E40: 63.072519 | F40: Relatively Low | G40: 51.701733 | H40: 15509842 | I40: 0 | J40: 3071733.3 | K40: 2056078.4
...

Sheet Inputs
B2: Climate Risk EAL Model | Inputs
B3: Gulf Coast Natural Gas Power Plant | Flood Expected Annual Loss
B5: 1. Asset Selection
B6: Plant (select) | C6: New Orleans Power
B7: Plant Code | C7: =INDEX(LA_Gas_Plants!$A$2:$A$55,MATCH($C$6,LA_Gas_Plants!$B$2:$B$55,0))
B8: Parish | C8: =VLOOKUP($C$6,LA_Gas_Plants!$B$2:$C$55,2,FALSE)
B9: Nameplate Capacity (MW) | C9: =SUMIF(Operable!$C$3:$C$26858,$C$7,Operable!$P$3:$P$26858)
B11: 2. Scenario and Valuation
B12: RCP Climate Scenario | C12: RCP 8.5
B13: Replacement Cost ($/kW) | C13: 1100 | D13: Adjustable assumption. Blended placeholder; CCGT overnight cost ~$700-1,300/kW.
B14: Asset Value ($) | C14: =C9*1000*C13 | D14: MW x 1,000 kW/MW x $/kW
B16: Legend
B17: Blue + shaded | C17: User input / selector (change these)
B18: Green | C18: Linked from another sheet
B19: Black | C19: Calculated on this sheet

Sheet EAL Calculation
B2: Expected Annual Loss Calculation
B3: Hybrid method: USACE depth-damage structure, calibrated to FEMA parish flood EAL
B5: A. FEMA Calibration Anchor | F5: B. Climate Assumptions (2050 horizon)
B6: Parish (from Inputs) | C6: =Inputs!C8 | F6: Active RCP Scenario (from Inputs) | G6: =Inputs!C12
B7: Parish Coastal Flood EAL (FEMA CFLD_EALT) | C7: =SUMIFS(NRI_Table_Counties!$BV$2:$BV$3233,NRI_Table_Counties!$F$2:$F$3233,$C$6,NRI_Table_Counties!$D$2:$D$3233,"LA") | F7: RCP 4.5 frequency multiplier | G7: 1.15 | H7: Assumed mid-century uplift on AEP
B8: Parish Riverine Flood EAL (FEMA IFLD_EALT) | C8: =SUMIFS(NRI_Table_Counties!$KU$2:$KU$3233,NRI_Table_Counties!$F$2:$F$3233,$C$6,NRI_Table_Counties!$D$2:$D$3233,"LA") | F8: RCP 8.5 frequency multiplier | G8: 1.3 | H8: Assumed mid-century uplift on AEP
B9: Parish Total Flood EAL | C9: =C7+C8 | F9: Active multiplier | G9: =IF(G6="RCP 8.5",G8,G7)
B10: Parish Building Value (FEMA BUILDVALUE) | C10: =SUMIFS(NRI_Table_Counties!$K$2:$K$3233,NRI_Table_Counties!$F$2:$F$3233,$C$6,NRI_Table_Counties!$D$2:$D$3233,"LA")
B11: Plant Asset Value (from Inputs) | C11: =Inputs!C14
B12: Plant Value Share of Parish | C12: =C11/C10
B13: Plant Baseline FEMA Flood EAL | C13: =C9*C12
B16: C. Return-Period Hazard Table
B17: Return Period (yr) | C17: Annual Exceedance Prob. | D17: Assumed Depth (ft) | E17: Damage % (interp.) | F17: Loss per Event (raw) | G17: EAL Contribution (raw) | H17: Prob. Mass (band)
B18: 10 | C18: 0.1 | D18: 0.5 | E18: =_xlfn.FORECAST.LINEAR(D18,OFFSET('Depth-Damage'!$B$3,FLOOR(D18,1),0,2,1),OFFSET('Depth-Damage'!$A$3,FLOOR(D18,1),0,2,1))/100 | F18: =$C$11*E18 | G18: =F18*H18 | H18: =C18-C19
B19: 25 | C19: 0.04 | D19: 1 | E19: =_xlfn.FORECAST.LINEAR(D19,OFFSET('Depth-Damage'!$B$3,FLOOR(D19,1),0,2,1),OFFSET('Depth-Damage'!$A$3,FLOOR(D19,1),0,2,1))/100 | F19: =$C$11*E19 | G19: =F19*H19 | H19: =C19-C20
B20: 50 | C20: 0.02 | D20: 2 | E20: =_xlfn.FORECAST.LINEAR(D20,OFFSET('Depth-Damage'!$B$3,FLOOR(D20,1),0,2,1),OFFSET('Depth-Damage'!$A$3,FLOOR(D20,1),0,2,1))/100 | F20: =$C$11*E20 | G20: =F20*H20 | H20: =C20-C21
B21: 100 | C21: 0.01 | D21: 3 | E21: =_xlfn.FORECAST.LINEAR(D21,OFFSET('Depth-Damage'!$B$3,FLOOR(D21,1),0,2,1),OFFSET('Depth-Damage'!$A$3,FLOOR(D21,1),0,2,1))/100 | F21: =$C$11*E21 | G21: =F21*H21 | H21: =C21-C22
B22: 200 | C22: 0.005 | D22: 4 | E22: =_xlfn.FORECAST.LINEAR(D22,OFFSET('Depth-Damage'!$B$3,FLOOR(D22,1),0,2,1),OFFSET('Depth-Damage'!$A$3,FLOOR(D22,1),0,2,1))/100 | F22: =$C$11*E22 | G22: =F22*H22 | H22: =C22-C23
B23: 500 | C23: 0.002 | D23: 6 | E23: =_xlfn.FORECAST.LINEAR(D23,OFFSET('Depth-Damage'!$B$3,FLOOR(D23,1),0,2,1),OFFSET('Depth-Damage'!$A$3,FLOOR(D23,1),0,2,1))/100 | F23: =$C$11*E23 | G23: =F23*H23 | H23: =C23
B24: Raw Base EAL (sum) | G24: =SUM(G18:G23)
B26: D. Calibrated EAL Results (RCP 4.5 vs RCP 8.5)
B27: Metric | C27: RCP 4.5 | D27: RCP 8.5
B28: Calibration Factor (to FEMA anchor) | C28: =$C$13/$G$24 | D28: =$C$13/$G$24
B29: Calibrated Base EAL | C29: =$G$24*C28 | D29: =$G$24*D28
B30: Climate Frequency Multiplier | C30: =$G$7 | D30: =$G$8
B31: Climate-Adjusted EAL ($/yr) | C31: =C29*C30 | D31: =D29*D30
B32: EAL as % of Asset Value | C32: =C31/$C$11 | D32: =D31/$C$11
B34: Method notes
B35: 1. Plant baseline EAL = FEMA parish flood EAL (coastal + riverine) scaled by plant value share of parish building stock. Assumes plant risk-per-dollar approximates parish average.
B36: 2. Depth-damage uses the USACE curve on the Depth-Damage tab; damage % linearly interpolated for fractional depths.
B37: 3. Assumed flood depths per return period (blue) are not site-derived. Replace with FEMA flood-map / BFE data per site to remove this assumption.
B38: 4. Raw depth-damage EAL is calibrated to the FEMA anchor via a single scaling factor, then amplified by an assumed climate frequency multiplier. Applying one multiplier to AEP is a simplification; real projections shift frequency and depth non-uniformly.

Sheet Monte Carlo
B2: Monte Carlo Simulation
B3: 10,000 simulated years of flood loss (lognormal, calibrated to climate-adjusted EAL)
B5: A. Simulation Drivers | F5: B. Simulated Annual Loss (10,000 draws) | I5: D. Loss Distribution (histogram bins)
B6: Active RCP Scenario (from Inputs) | C6: =Inputs!C12 | F6: Sim # | G6: Simulated Loss ($) | I6: Bin Upper ($) | J6: Bin Label | K6: Frequency
B7: Target Mean EAL ($/yr) | C7: =IF(C6="RCP 8.5",'EAL Calculation'!D31,'EAL Calculation'!C31) | D7: Climate-adjusted EAL for active scenario | F7: =1 | G7: =EXP($C$12+$C$8*_xlfn.NORM.S.INV(RAND())) | I7: =$C$19*1/12 | J7: ="<= "&TEXT(I7,"$#,##0") | K7: {=FREQUENCY(G7:G10006,I7:I18)}
B8: Volatility (sigma of underlying normal) | C8: 1 | D8: ASSUMED. Key tail driver; not site-derived | F8: =F7+1 | G8: =EXP($C$12+$C$8*_xlfn.NORM.S.INV(RAND())) | I8: =$C$19*2/12 | J8: ="<= "&TEXT(I8,"$#,##0")
B9: Time Horizon (years) | C9: 5 | D9: Multiplies mean for multi-year loss | F9: =F8+1 | G9: =EXP($C$12+$C$8*_xlfn.NORM.S.INV(RAND())) | I9: =$C$19*3/12 | J9: ="<= "&TEXT(I9,"$#,##0")
B10: Confidence Level (VaR / CVaR) | C10: 0.95 | D10: e.g. 0.95 = 95% | F10: =F9+1 | G10: =EXP($C$12+$C$8*_xlfn.NORM.S.INV(RAND())) | I10: =$C$19*4/12 | J10: ="<= "&TEXT(I10,"$#,##0")
B11: Number of Simulations | C11: 10000 | D11: Fixed at 10,000 rows | F11: =F10+1 | G11: =EXP($C$12+$C$8*_xlfn.NORM.S.INV(RAND())) | I11: =$C$19*5/12 | J11: ="<= "&TEXT(I11,"$#,##0")
B12: Derived mu (lognormal location) | C12: =LN(C7*C9)-(C8^2)/2 | D12: mu = LN(mean) - sigma^2/2 | F12: =F11+1 | G12: =EXP($C$12+$C$8*_xlfn.NORM.S.INV(RAND())) | I12: =$C$19*6/12 | J12: ="<= "&TEXT(I12,"$#,##0")
F13: =F12+1 | G13: =EXP($C$12+$C$8*_xlfn.NORM.S.INV(RAND())) | I13: =$C$19*7/12 | J13: ="<= "&TEXT(I13,"$#,##0")
B14: C. Risk Statistics | F14: =F13+1 | G14: =EXP($C$12+$C$8*_xlfn.NORM.S.INV(RAND())) | I14: =$C$19*8/12 | J14: ="<= "&TEXT(I14,"$#,##0")
B15: Simulated Mean Loss | C15: =AVERAGE(G7:G10006) | F15: =F14+1 | G15: =EXP($C$12+$C$8*_xlfn.NORM.S.INV(RAND())) | I15: =$C$19*9/12 | J15: ="<= "&TEXT(I15,"$#,##0")
B16: Target Mean EAL (check) | C16: =C7*C9 | F16: =F15+1 | G16: =EXP($C$12+$C$8*_xlfn.NORM.S.INV(RAND())) | I16: =$C$19*10/12 | J16: ="<= "&TEXT(I16,"$#,##0")
B17: Std Deviation | C17: =_xlfn.STDEV.S(G7:G10006) | F17: =F16+1 | G17: =EXP($C$12+$C$8*_xlfn.NORM.S.INV(RAND())) | I17: =$C$19*11/12 | J17: ="<= "&TEXT(I17,"$#,##0")
B18: Minimum | C18: =MIN(G7:G10006) | F18: =F17+1 | G18: =EXP($C$12+$C$8*_xlfn.NORM.S.INV(RAND())) | I18: =$C$19*12/12 | J18: ="<= "&TEXT(I18,"$#,##0")
B19: Maximum | C19: =MAX(G7:G10006) | F19: =F18+1 | G19: =EXP($C$12+$C$8*_xlfn.NORM.S.INV(RAND()))
B20: VaR at Confidence Level | C20: =_xlfn.PERCENTILE.INC(G7:G10006,$C$10) | F20: =F19+1 | G20: =EXP($C$12+$C$8*_xlfn.NORM.S.INV(RAND()))
B21: CVaR (Expected Shortfall) | C21: =AVERAGEIF(G7:G10006,">"&C20) | F21: =F20+1 | G21: =EXP($C$12+$C$8*_xlfn.NORM.S.INV(RAND()))
B22: VaR as % of Asset Value | C22: =C20/Inputs!C14 | F22: =F21+1 | G22: =EXP($C$12+$C$8*_xlfn.NORM.S.INV(RAND()))
F23: =F22+1 | G23: =EXP($C$12+$C$8*_xlfn.NORM.S.INV(RAND()))
F24: =F23+1 | G24: =EXP($C$12+$C$8*_xlfn.NORM.S.INV(RAND()))
F25: =F24+1 | G25: =EXP($C$12+$C$8*_xlfn.NORM.S.INV(RAND()))
F26: =F25+1 | G26: =EXP($C$12+$C$8*_xlfn.NORM.S.INV(RAND()))
F27: =F26+1 | G27: =EXP($C$12+$C$8*_xlfn.NORM.S.INV(RAND()))
F28: =F27+1 | G28: =EXP($C$12+$C$8*_xlfn.NORM.S.INV(RAND()))
F29: =F28+1 | G29: =EXP($C$12+$C$8*_xlfn.NORM.S.INV(RAND()))
F30: =F29+1 | G30: =EXP($C$12+$C$8*_xlfn.NORM.S.INV(RAND()))
F31: =F30+1 | G31: =EXP($C$12+$C$8*_xlfn.NORM.S.INV(RAND()))
F32: =F31+1 | G32: =EXP($C$12+$C$8*_xlfn.NORM.S.INV(RAND()))
F33: =F32+1 | G33: =EXP($C$12+$C$8*_xlfn.NORM.S.INV(RAND()))
F34: =F33+1 | G34: =EXP($C$12+$C$8*_xlfn.NORM.S.INV(RAND()))
... F10006: =F10005+1 | G10006: =EXP($C$12+$C$8*_xlfn.NORM.S.INV(RAND()))

Sheet Resilience ROI
B2: Resilience Investment ROI
B3: Flood mitigation cost vs avoided expected annual loss (benefit-cost analysis)
B5: A. Mitigation Inputs | F5: C. With vs Without Mitigation (annual)
B6: Active RCP Scenario (from Inputs) | C6: =Inputs!C12 | F6: Item | G6: Without | H6: With
B7: Baseline Climate-Adjusted EAL ($/yr) | C7: =IF(C6="RCP 8.5",'EAL Calculation'!D31,'EAL Calculation'!C31) | D7: Active scenario, from EAL Calculation | F7: Expected Annual Loss | G7: =C7 | H7: =C7-C15
B8: Mitigation Capital Cost ($) | C8: 15000000 | D8: ASSUMED placeholder. Replace with measure-specific cost | F8: Annual Maintenance | G8: =0 | H8: =C10
B9: Loss Reduction (%) | C9: 0.65 | D9: ASSUMED. Effectiveness of the measure | F9: Total Annual Cost | G9: =G7+G8 | H9: =H7+H8
B10: Annual Maintenance Cost ($/yr) | C10: 150000 | D10: ASSUMED. Upkeep of the measure
B11: Discount Rate | C11: 0.08 | F11: D. Break-Even (to reach BCR = 1)
B12: Analysis Period (years) | C12: 30 | F12: Annuity factor (PV of $1/yr) | G12: =PV($C$11,$C$12,-1)
F13: Max justifiable mitigation cost | G13: =$C$16*$G$12
B14: B. Benefit-Cost Results | F14: Min baseline EAL needed (this cost) | G14: =(($C$8/$G$12)+$C$10)/$C$9
B15: Avoided Loss ($/yr) | C15: =C7*C9 | F15: Implied site exposure factor | G15: =$G$14/$C$7
B16: Net Annual Benefit ($/yr) | C16: =C15-C10
B17: Simple Payback (years) | C17: =IF(C16>0,C8/C16,"n/a")
B18: PV of Net Benefits | C18: =PV(C11,C12,-C16)
B19: Mitigation Capital Cost | C19: =C8
B20: Net Present Value (NPV) | C20: =C18-C19
B21: Benefit-Cost Ratio (BCR) | C21: =C18/C19
B22: Decision | C22: =IF(C20>0,"Invest (NPV positive, BCR > 1)","Do not invest (NPV negative)")
B24: Method notes
B25: 1. Benefit = avoided EAL (baseline climate-adjusted EAL x loss reduction %). Costs = upfront capital + annual maintenance. Standard FEMA benefit-cost framing.
B26: 2. NPV discounts the net annual benefit over the analysis period; BCR = PV of benefits / capital cost. Invest if NPV > 0 (BCR > 1).
B27: 3. Mitigation cost, loss reduction %, and maintenance are ASSUMED placeholders (blue), not measure- or site-specific. They drive the entire result.
B28: 4. Break-even block shows the baseline EAL (and implied site exposure factor vs parish average) required for the investment to clear. Use it to test whether the plant's true exposure justifies mitigation.

Sheet Depth-Damage
A1: Depth-Percent Damage Relationships (Direct Damage)
A2: Depth (feet) | B2: Percent Damage
A3: 0 | B3: 0
A4: 1 | B4: 32
A5: 2 | B5: 38.7
A6: 3 | B6: 45.5
A7: 4 | B7: 52.2
A8: 5 | B8: 58.6
A9: 6 | B9: 64.5
A10: 7 | B10: 69.8
A11: 8 | B11: 74.2
A12: 9 | B12: 77.7
A14: Source: USACE generic depth-percent damage curve (structure, direct damage). Percent values expressed 0-100; divide by 100 when applied.

Sheet LA_Gas_Plants
A1: Plant Code | B1: Plant Name | C1: Parish | D1: Nameplate MW | E1: Generating Units | F1: Prime Movers
A2: 1403 | B2: Nine Mile Point | C2: Jefferson | D2: 2439.7 | E2: 5 | F2: CA,CT,ST
A3: 55173 | B3: Acadia Energy Center | C3: Acadia | D3: 1389.2 | E3: 6 | F3: CA,CT
A4: 55419 | B4: Plaquemine Cogeneration Plant | C4: Iberville | D4: 1084.8 | E4: 7 | F4: CA,CT
A5: 1402 | B5: Little Gypsy | C5: St Charles | D5: 1002.9 | E5: 2 | F5: ST
A6: 60926 | B6: St. Charles Power Station (LA) | C6: St Charles | D6: 1000 | E6: 3 | F6: CA,CT
A7: 60927 | B7: Lake Charles Power | C7: Calcasieu | D7: 1000 | E7: 3 | F7: CA,CT
A8: 1396 | B8: Coughlin Power Station | C8: Evangeline | D8: 922.8 | E8: 5 | F8: CA,CT
A9: 55467 | B9: Ouachita | C9: Ouachita | D9: 903.9 | E9: 6 | F9: CA,CT
A10: 55089 | B10: Taft Cogeneration Facility | C10: St Charles | D10: 894.2 | E10: 4 | F10: CA,CT
A11: 55620 | B11: Perryville Power Station | C11: Ouachita | D11: 824.1 | E11: 4 | F11: CA,CT,GT
A12: 6055 | B12: Big Cajun 2 | C12: Pointe Coupee | D12: 626 | E12: 1 | F12: ST
A13: 56565 | B13: J Lamar Stall Unit | C13: Caddo | D13: 624 | E13: 3 | F13: CA,CT
... A55: 50490 | B55: PPG Plant C Caustic | C55: Calcasieu | D55: 3.4 | E55: 1 | F55: ST
