Workbook

Sheet Data PLNTR
A1: Date | B1: Open | C1: High | D1: Low | E1: Close | F1: Adj Close | G1: Volume | H1: Daily Log-Return | I1: ORCL Ret (date-matched)
A2: 46178 | B2: 140.32 | C2: 141.97 | D2: 134.02 | E2: 135.53 | F2: 135.53 | G2: 38108100 | H2: =LN(F2/F3) -> -0.044519129 | I2: =IFERROR(_xlfn.XLOOKUP(A2,' Data ORCL'!$A$2:$A$1260,' Data ORCL'!$H$2:$H$1260),"") -> -0.10079188
A3: 46177 | B3: 145.46 | C3: 146.37 | D3: 140.27 | E3: 141.7 | F3: 141.7 | G3: 40834000 | H3: =LN(F3/F4) -> -0.0035223707 | I3: =IFERROR(_xlfn.XLOOKUP(A3,' Data ORCL'!$A$2:$A$1260,' Data ORCL'!$H$2:$H$1260),"") -> 0.025758383
A4: 46176 | B4: 149.7 | C4: 151.68 | D4: 141.25 | E4: 142.2 | F4: 142.2 | G4: 41072500 | H4: =LN(F4/F5) -> -0.0677638 | I4: =IFERROR(_xlfn.XLOOKUP(A4,' Data ORCL'!$A$2:$A$1260,' Data ORCL'!$H$2:$H$1260),"") -> -0.060029391
A5: 46175 | B5: 156.69 | C5: 159.55 | D5: 149.8 | E5: 152.17 | F5: 152.17 | G5: 43163100 | H5: =LN(F5/F6) -> -0.054229769 | I5: =IFERROR(_xlfn.XLOOKUP(A5,' Data ORCL'!$A$2:$A$1260,' Data ORCL'!$H$2:$H$1260),"") -> -0.014490948
A6: 46174 | B6: 159.98 | C6: 163.7 | D6: 155.88 | E6: 160.65 | F6: 160.65 | G6: 57654000 | H6: =LN(F6/F7) -> 0.025916517 | I6: =IFERROR(_xlfn.XLOOKUP(A6,' Data ORCL'!$A$2:$A$1260,' Data ORCL'!$H$2:$H$1260),"") -> 0.094472328
A7: 46171 | B7: 147.82 | C7: 157.78 | D7: 145.79 | E7: 156.54 | F7: 156.54 | G7: 92196600 | H7: =LN(F7/F8) -> 0.088092138 | I7: =IFERROR(_xlfn.XLOOKUP(A7,' Data ORCL'!$A$2:$A$1260,' Data ORCL'!$H$2:$H$1260),"") -> 0.10291275
A8: 46170 | B8: 133.16 | C8: 145 | D8: 133 | E8: 143.34 | F8: 143.34 | G8: 52085200 | H8: =LN(F8/F9) -> 0.078561316 | I8: =IFERROR(_xlfn.XLOOKUP(A8,' Data ORCL'!$A$2:$A$1260,' Data ORCL'!$H$2:$H$1260),"") -> 0.064584341
A9: 46169 | B9: 133.3 | C9: 135.73 | D9: 131.63 | E9: 132.51 | F9: 132.51 | G9: 34159800 | H9: =LN(F9/F10) -> -0.030398833 | I9: =IFERROR(_xlfn.XLOOKUP(A9,' Data ORCL'!$A$2:$A$1260,' Data ORCL'!$H$2:$H$1260),"") -> -0.010937039
A10: 46168 | B10: 136.16 | C10: 138.68 | D10: 133.3 | E10: 136.6 | F10: 136.6 | G10: 31723900 | H10: =LN(F10/F11) -> -0.0020476824 | I10: =IFERROR(_xlfn.XLOOKUP(A10,' Data ORCL'!$A$2:$A$1260,' Data ORCL'!$H$2:$H$1260),"") -> 0.0050890695
A11: 46164 | B11: 137.43 | C11: 139.02 | D11: 134.3 | E11: 136.88 | F11: 136.88 | G11: 27578000 | H11: =LN(F11/F12) -> -0.0038645278 | I11: =IFERROR(_xlfn.XLOOKUP(A11,' Data ORCL'!$A$2:$A$1260,' Data ORCL'!$H$2:$H$1260),"") -> 0.012099139
A12: 46163 | B12: 135.8 | C12: 138.55 | D12: 135.42 | E12: 137.41 | F12: 137.41 | G12: 24311900 | H12: =LN(F12/F13) -> 0.00189394 | I12: =IFERROR(_xlfn.XLOOKUP(A12,' Data ORCL'!$A$2:$A$1260,' Data ORCL'!$H$2:$H$1260),"") -> 0.0085201479
A13: 46162 | B13: 134.15 | C13: 137.24 | D13: 132.42 | E13: 137.15 | F13: 137.15 | G13: 31307700 | H13: =LN(F13/F14) -> 0.013876365 | I13: =IFERROR(_xlfn.XLOOKUP(A13,' Data ORCL'!$A$2:$A$1260,' Data ORCL'!$H$2:$H$1260),"") -> 0.036257421
... A1258: 44355 | B1258: 24.85 | C1258: 25.23 | D1258: 23.93 | E1258: 24.38 | F1258: 24.38 | G1258: 53488600 | H1258: =LN(F1258/F1259) -> -0.0032760062 | I1258: =IFERROR(_xlfn.XLOOKUP(A1258,' Data ORCL'!$A$2:$A$1260,' Data ORCL'!$H$2:$H$1260),"")
A1259: 44354 | B1259: 24 | C1259: 24.76 | D1259: 23.79 | E1259: 24.46 | F1259: 24.46 | G1259: 49641000

Sheet  Data ORCL
A1: Date | B1: Open | C1: High | D1: Low | E1: Close | F1: Adj Close | G1: Volume | H1: Daily Log-Return
A2: 46178 | B2: 229.49 | C2: 231.44 | D2: 209.45 | E2: 213.68 | F2: 213.68 | G2: 28891400 | H2: =LN(F2/F3) -> -0.10079188
A3: 46177 | B3: 227 | C3: 238.95 | D3: 224 | E3: 236.34 | F3: 236.34 | G3: 19993800 | H3: =LN(F3/F4) -> 0.025758383
A4: 46176 | B4: 240.48 | C4: 240.51 | D4: 227.61 | E4: 230.33 | F4: 230.33 | G4: 23644700 | H4: =LN(F4/F5) -> -0.060029391
A5: 46175 | B5: 242.8 | C5: 249 | D5: 238.84 | E5: 244.58 | F5: 244.58 | G5: 30294800 | H5: =LN(F5/F6) -> -0.014490948
A6: 46174 | B6: 230.5 | C6: 250.25 | D6: 224.6 | E6: 248.15 | F6: 248.15 | G6: 48390000 | H6: =LN(F6/F7) -> 0.094472328
A7: 46171 | B7: 209 | C7: 226.29 | D7: 208.01 | E7: 225.78 | F7: 225.78 | G7: 41082200 | H7: =LN(F7/F8) -> 0.10291275
A8: 46170 | B8: 194.04 | C8: 205 | D8: 193.38 | E8: 203.7 | F8: 203.7 | G8: 25339900 | H8: =LN(F8/F9) -> 0.064584341
A9: 46169 | B9: 191.48 | C9: 192.14 | D9: 187.92 | E9: 190.96 | F9: 190.96 | G9: 12126000 | H9: =LN(F9/F10) -> -0.010937039
A10: 46168 | B10: 193.3 | C10: 195.2 | D10: 190.56 | E10: 193.06 | F10: 193.06 | G10: 12856100 | H10: =LN(F10/F11) -> 0.0050890695
A11: 46164 | B11: 191.67 | C11: 197 | D11: 191.1 | E11: 192.08 | F11: 192.08 | G11: 10875800 | H11: =LN(F11/F12) -> 0.012099139
A12: 46163 | B12: 189.01 | C12: 192.82 | D12: 187.2 | E12: 189.77 | F12: 189.77 | G12: 12119700 | H12: =LN(F12/F13) -> 0.0085201479
A13: 46162 | B13: 179.94 | C13: 188.22 | D13: 178.8 | E13: 188.16 | F13: 188.16 | G13: 16517200 | H13: =LN(F13/F14) -> 0.036257421
... A41: 46122 | B41: 137.32 | C41: 140.17 | D41: 134.57 | E41: 138.09 | F41: 138.09 | G41: 26171800 | H41: =LN(F41/F42) -> #DIV/0!
A42: 46121 | B42: 0.5 Dividend | H42: =LN(F42/F43) -> #NUM!
A43: 46121 | B43: 142.2 | C43: 142.8 | D43: 136 | E43: 137.86 | F43: 137.86 | G43: 30407800 | H43: =LN(F43/F44) -> -0.037724208
A44: 46120 | B44: 150.3 | C44: 151.46 | D44: 142.9 | E44: 143.66 | F44: 143.16 | G44: 23527000 | H44: =LN(F44/F45) -> 0.0034286148
A45: 46119 | B45: 143.78 | C45: 144.57 | D45: 139.94 | E45: 143.17 | F45: 142.67 | G45: 17250400 | H45: =LN(F45/F46) -> -0.016406346
A46: 46118 | B46: 147.44 | C46: 148.55 | D46: 143.85 | E46: 145.54 | F46: 145.03 | G46: 12556700 | H46: =LN(F46/F47) -> -0.0057751965
A47: 46114 | B47: 142.78 | C47: 146.44 | D47: 140.3 | E47: 146.38 | F47: 145.87 | G47: 14381900 | H47: =LN(F47/F48) -> 0.007914973
A48: 46113 | B48: 149.09 | C48: 149.65 | D48: 144.67 | E48: 145.23 | F48: 144.72 | G48: 20495900 | H48: =LN(F48/F49) -> -0.012906948
A49: 46112 | B49: 140.3 | C49: 147.4 | D49: 139.85 | E49: 147.11 | F49: 146.6 | G49: 24492000 | H49: =LN(F49/F50) -> 0.058137948
A50: 46111 | B50: 140.04 | C50: 141.2 | D50: 136.95 | E50: 138.8 | F50: 138.32 | G50: 20125700 | H50: =LN(F50/F51) -> -0.0061263661
A51: 46108 | B51: 140.93 | C51: 141.69 | D51: 138.3 | E51: 139.66 | F51: 139.17 | G51: 17929600 | H51: =LN(F51/F52) -> -0.022311569
A52: 46107 | B52: 143.89 | C52: 146.47 | D52: 142.54 | E52: 142.81 | F52: 142.31 | G52: 16961900 | H52: =LN(F52/F53) -> -0.022237036
A53: 46106 | B53: 149.23 | C53: 149.84 | D53: 144.6 | E53: 146.02 | F53: 145.51 | G53: 20683800 | H53: =LN(F53/F54) -> -0.0073265417
A54: 46105 | B54: 153 | C54: 153.9 | D54: 146.85 | E54: 147.09 | F54: 146.58 | G54: 26122100 | H54: =LN(F54/F55) -> -0.048081703
... A103: 46034 | B103: 197.6 | C103: 206.6 | D103: 197.01 | E103: 204.68 | F103: 203.97 | G103: 25428500 | H103: =LN(F103/F104) -> #DIV/0!
A104: 46031 | B104: 0.5 Dividend | H104: =LN(F104/F105) -> #NUM!
A105: 46031 | B105: 191.66 | C105: 200.18 | D105: 188.78 | E105: 198.52 | F105: 197.83 | G105: 26152700 | H105: =LN(F105/F106) -> 0.048363121
A106: 46030 | B106: 190.88 | C106: 190.95 | D106: 186.15 | E106: 189.65 | F106: 188.49 | G106: 19468500 | H106: =LN(F106/F107) -> -0.016678014
A107: 46029 | B107: 195.3 | C107: 195.67 | D107: 192 | E107: 192.84 | F107: 191.66 | G107: 11171200 | H107: =LN(F107/F108) -> -0.0047367551
A108: 46028 | B108: 192.56 | C108: 194.88 | D108: 190.7 | E108: 193.75 | F108: 192.57 | G108: 16474500 | H108: =LN(F108/F109) -> 0.0060419997
A109: 46027 | B109: 198.34 | C109: 201.69 | D109: 192.33 | E109: 192.59 | F109: 191.41 | G109: 22635500 | H109: =LN(F109/F110) -> -0.016065851
A110: 46024 | B110: 197.47 | C110: 198.59 | D110: 194.21 | E110: 195.71 | F110: 194.51 | G110: 14540700 | H110: =LN(F110/F111) -> 0.0040697581
A111: 46022 | B111: 196.42 | C111: 197.2 | D111: 194.73 | E111: 194.91 | F111: 193.72 | G111: 10341500 | H111: =LN(F111/F112) -> -0.011751861
A112: 46021 | B112: 196.06 | C112: 198.38 | D112: 195.71 | E112: 197.21 | F112: 196.01 | G112: 14197400 | H112: =LN(F112/F113) -> 0.0093286171
A113: 46020 | B113: 194.16 | C113: 198.51 | D113: 192.64 | E113: 195.38 | F113: 194.19 | G113: 14748100 | H113: =LN(F113/F114) -> -0.013249292
A114: 46017 | B114: 198.06 | C114: 200.37 | D114: 196.11 | E114: 197.99 | F114: 196.78 | G114: 11262000 | H114: =LN(F114/F115) -> 0.0025441422
A115: 46015 | B115: 195 | C115: 198.28 | D115: 194.42 | E115: 197.49 | F115: 196.28 | G115: 9282700 | H115: =LN(F115/F116) -> 0.010911155
...

Sheet Simulations
A1: Sim # | B1: Log-Return (21-Day) | C1: Simple Return (%) | D1: P&L per Share ($) | E1: In Loss Tail? (< VaR)
A2: 1 | B2: ='Monte Carlo VaR'!$C$17+_xlfn.NORM.S.INV(RAND())*'Monte Carlo VaR'!$C$18 -> -0.063009624 | C2: =(EXP(B2)-1)*100 -> -6.1065562 | D2: ='Monte Carlo VaR'!$B$9*(EXP(B2)-1) -> -8.2762157 | E2: =IF(B2<='Monte Carlo VaR'!$B$25,"YES ◀ TAIL","")
A3: 2 | B3: ='Monte Carlo VaR'!$C$17+_xlfn.NORM.S.INV(RAND())*'Monte Carlo VaR'!$C$18 -> 0.0063037795 | C3: =(EXP(B3)-1)*100 -> 0.63236901 | D3: ='Monte Carlo VaR'!$B$9*(EXP(B3)-1) -> 0.85704972 | E3: =IF(B3<='Monte Carlo VaR'!$B$25,"YES ◀ TAIL","")
A4: 3 | B4: ='Monte Carlo VaR'!$C$17+_xlfn.NORM.S.INV(RAND())*'Monte Carlo VaR'!$C$18 -> -0.035699996 | C4: =(EXP(B4)-1)*100 -> -3.5070268 | D4: ='Monte Carlo VaR'!$B$9*(EXP(B4)-1) -> -4.7530734 | E4: =IF(B4<='Monte Carlo VaR'!$B$25,"YES ◀ TAIL","")
A5: 4 | B5: ='Monte Carlo VaR'!$C$17+_xlfn.NORM.S.INV(RAND())*'Monte Carlo VaR'!$C$18 -> -0.030625172 | C5: =(EXP(B5)-1)*100 -> -3.0160972 | D5: ='Monte Carlo VaR'!$B$9*(EXP(B5)-1) -> -4.0877166 | E5: =IF(B5<='Monte Carlo VaR'!$B$25,"YES ◀ TAIL","")
A6: 5 | B6: ='Monte Carlo VaR'!$C$17+_xlfn.NORM.S.INV(RAND())*'Monte Carlo VaR'!$C$18 -> 0.25160427 | C6: =(EXP(B6)-1)*100 -> 28.6087 | D6: ='Monte Carlo VaR'!$B$9*(EXP(B6)-1) -> 38.77337 | E6: =IF(B6<='Monte Carlo VaR'!$B$25,"YES ◀ TAIL","")
A7: 6 | B7: ='Monte Carlo VaR'!$C$17+_xlfn.NORM.S.INV(RAND())*'Monte Carlo VaR'!$C$18 -> 0.49629815 | C7: =(EXP(B7)-1)*100 -> 64.262924 | D7: ='Monte Carlo VaR'!$B$9*(EXP(B7)-1) -> 87.095541 | E7: =IF(B7<='Monte Carlo VaR'!$B$25,"YES ◀ TAIL","")
A8: 7 | B8: ='Monte Carlo VaR'!$C$17+_xlfn.NORM.S.INV(RAND())*'Monte Carlo VaR'!$C$18 -> -0.11109887 | C8: =(EXP(B8)-1)*100 -> -10.514973 | D8: ='Monte Carlo VaR'!$B$9*(EXP(B8)-1) -> -14.250943 | E8: =IF(B8<='Monte Carlo VaR'!$B$25,"YES ◀ TAIL","")
A9: 8 | B9: ='Monte Carlo VaR'!$C$17+_xlfn.NORM.S.INV(RAND())*'Monte Carlo VaR'!$C$18 -> -0.11351179 | C9: =(EXP(B9)-1)*100 -> -10.730633 | D9: ='Monte Carlo VaR'!$B$9*(EXP(B9)-1) -> -14.543227 | E9: =IF(B9<='Monte Carlo VaR'!$B$25,"YES ◀ TAIL","")
A10: 9 | B10: ='Monte Carlo VaR'!$C$17+_xlfn.NORM.S.INV(RAND())*'Monte Carlo VaR'!$C$18 -> -0.055899419 | C10: =(EXP(B10)-1)*100 -> -5.4365756 | D10: ='Monte Carlo VaR'!$B$9*(EXP(B10)-1) -> -7.3681909 | E10: =IF(B10<='Monte Carlo VaR'!$B$25,"YES ◀ TAIL","")
A11: 10 | B11: ='Monte Carlo VaR'!$C$17+_xlfn.NORM.S.INV(RAND())*'Monte Carlo VaR'!$C$18 -> -0.10954131 | C11: =(EXP(B11)-1)*100 -> -10.375486 | D11: ='Monte Carlo VaR'!$B$9*(EXP(B11)-1) -> -14.061896 | E11: =IF(B11<='Monte Carlo VaR'!$B$25,"YES ◀ TAIL","")
A12: 11 | B12: ='Monte Carlo VaR'!$C$17+_xlfn.NORM.S.INV(RAND())*'Monte Carlo VaR'!$C$18 -> 0.12352178 | C12: =(EXP(B12)-1)*100 -> 13.147465 | D12: ='Monte Carlo VaR'!$B$9*(EXP(B12)-1) -> 17.818759 | E12: =IF(B12<='Monte Carlo VaR'!$B$25,"YES ◀ TAIL","")
A13: 12 | B13: ='Monte Carlo VaR'!$C$17+_xlfn.NORM.S.INV(RAND())*'Monte Carlo VaR'!$C$18 -> 0.097594601 | C13: =(EXP(B13)-1)*100 -> 10.251574 | D13: ='Monte Carlo VaR'!$B$9*(EXP(B13)-1) -> 13.893958 | E13: =IF(B13<='Monte Carlo VaR'!$B$25,"YES ◀ TAIL","")
... A10001: 10000 | B10001: ='Monte Carlo VaR'!$C$17+_xlfn.NORM.S.INV(RAND())*'Monte Carlo VaR'!$C$18 -> -0.017749113 | C10001: =(EXP(B10001)-1)*100 -> -1.7592525 | D10001: ='Monte Carlo VaR'!$B$9*(EXP(B10001)-1) -> -2.3843149 | E10001: =IF(B10001<='Monte Carlo VaR'!$B$25,"YES ◀ TAIL","")

Sheet Monte Carlo VaR
A1: PALANTIR TECHNOLOGIES (PLTR)
A2: Monte Carlo Value at Risk (VaR)
A3: Holding Period | 10,000 Simulations | Log-Normal Returns | Full Dataset Jun 2022 – Jun 2026
A5: 1. INPUT PARAMETERS
A6: Ticker | B6: PLTR
A7: Data Window | B7: Jun 2022 – Jun 2026
A8: Historical Observations (n) | B8: =COUNTA('Data PLNTR'!F2:F1259)-1 -> 1257
A9: Latest Closing Price ($) | B9: =INDEX('Data PLNTR'!F2:F1259,MATCH(MAX('Data PLNTR'!A2:A1259),'Data PLNTR'!A2:A1259,0)) -> 135.53
A10: Holding Period (Trading Days) | B10: 21
A11: Confidence Level | B11: 0.95
A12: Number of Simulations | B12: 10000
A13: Random Seed | B13: 42
A15: 2. HISTORICAL RETURN STATISTICS | F15: 2b. TAIL-RISK DIAGNOSTICS (Fat Tails)
A16: Parameter | B16: 1-Day (Log-Return) | C16: 21-Day Scaled | D16: Annualized (×252) | F16: Diagnostic | G16: Value
A17: Mean Return (μ) | B17: 0.002826 | C17: =B17*B10 -> 0.059346 | D17: =B17*252 -> 0.712152 | F17: Skewness | G17: =SKEW('Data PLNTR'!H2:H1258) -> 0.38843658
A18: Std Dev of Returns (σ) | B18: 0.04034 | C18: =B18*SQRT(B10) -> 0.1848611 | D18: =B18*SQRT(252) -> 0.64037765 | F18: Excess Kurtosis (Excel KURT) | G18: =KURT('Data PLNTR'!H2:H1258) -> 5.3443868
A19: Variance (σ²) | B19: =B18^2 -> 0.0016273156 | C19: =C18^2 -> 0.034173628 | F19: Total Kurtosis (=3 if normal) | G19: =G18+3 -> 8.3443868
A20: Z-Score (95% VaR cutoff) | B20: =_xlfn.NORM.S.INV(1-B11) -> -1.6448536 | F20: Fat tails vs. Normal? | G20: =IF(G19>3,"YES — fatter than normal","No") -> YES — fatter than normal
A21: Parametric VaR (μ + Zσ) | B21: =C17+B20*C18 -> -0.24472346 | C21: =(EXP(B21)-1)*B9 -> -29.420714
F22: 2c. STUDENT'S t-VaR (Fat-Tailed)
A23: 3. MONTE CARLO VaR RESULTS | F23: Parameter | G23: Value
A24: Metric | B24: Log-Return | C24: $ P&L per Share | D24: Formula Used | F24: Implied Deg. of Freedom (ν) | G24: =MAX(5,6/G18+4) -> 5.1226732
A25: Value at Risk (VaR) — 95% | B25: =PERCENTILE(Simulations!B2:B10001,1-B11) -> -0.24862478 | C25: =(EXP(B25)-1)*B9 -> -29.833874 | D25: =PERCENTILE(Simulations!B, 5%) | F25: t critical value @ 5% (ν) | G25: =_xlfn.T.INV(1-B11,G24) -> -2.0150484
A26: CVaR / Expected Shortfall — 95% | B26: =AVERAGEIF(Simulations!B2:B10001,"<="&B25,Simulations!B2:B10001) -> -0.32677067 | C26: =(EXP(B26)-1)*B9 -> -37.779105 | D26: =AVERAGEIF(B_sims, "≤ VaR") | F26: Std. scale factor √(ν/(ν-2)) | G26: =SQRT(G24/(G24-2)) -> 1.280811
A27: Mean Simulated Return | B27: =AVERAGE(Simulations!B2:B10001) -> 0.060271944 | C27: =(EXP(B27)-1)*B9 -> 8.4198481 | D27: =AVERAGE(Simulations!B) | F27: t-VaR (21-Day Log-Return) | G27: =C17+(G25/G26)*C18 -> -0.23148853
A28: Std Dev of Simulated Returns | B28: =STDEV(Simulations!B2:B10001) -> 0.18699971 | D28: =STDEV(Simulations!B) | F28: t-VaR ($ P&L per Share) | G28: =(EXP(G27)-1)*B9 -> -28.007031
A29: Best Return (99th Pctile) | B29: =PERCENTILE(Simulations!B2:B10001,0.99) -> 0.49256414 | C29: =(EXP(B29)-1)*B9 -> 86.265805 | D29: =PERCENTILE(Simulations!B, 99%) | F29: vs. Normal Parametric VaR ($) | G29: =G28-C21 -> 1.4136835
A30: Worst Return (1st Pctile) | B30: =PERCENTILE(Simulations!B2:B10001,0.01) -> -0.37164536 | C30: =(EXP(B30)-1)*B9 -> -42.06868 | D30: =PERCENTILE(Simulations!B, 1%) | F30: t-VaR @ 99% (1% tail, log-ret) | G30: =C17+(_xlfn.T.INV(0.01,G24)/G26)*C18 -> -0.42631868
A31: PLTR Floor Price (VaR scenario) | B31: =B9*(EXP(B25)) -> 105.69613 | D31: =LatestPrice × exp(VaR%) | F31: Normal VaR @ 99% (log-ret) | G31: =C17+_xlfn.NORM.S.INV(0.01)*C18 -> -0.37070524
A32: INTERPRETATION
A33: INTERPRETATION | F33: 2d. HISTORICAL SIMULATION VaR
A34: With 95% confidence, the maximum 21-day loss per PLTR share will NOT exceed: | B34: =C25 -> -29.833874 | F34: Metric | G34: Value
A35: Expressed as a return: | B35: =B25 -> -0.24862478 | F35: Hist. 5th Pctile (1-Day) | G35: =PERCENTILE('Data PLNTR'!H2:H1258,1-B11) -> -0.063968429
A36: Worst-case floor price (VaR scenario): | B36: =B31 -> 105.69613 | F36: Hist. VaR (21-Day, √T scaled) | G36: =G35*SQRT(B10) -> -0.29314017
A37: There is a 5% probability that loss EXCEEDS the VaR. In those tail scenarios, the average loss (CVaR) is: | B37: =C26 -> -37.779105 | F37: Hist. VaR ($ P&L per Share) | G37: =(EXP(G36)-1)*B9 -> -34.43579
A38: 4. SIMULATED RETURN DISTRIBUTION (10,000 Scenarios)
A39: 4. SIMULATED RETURN DISTRIBUTION (10,000 Scenarios — 21-Day Log-Return) | F39: VaR METHOD COMPARISON ($/share, 21-Day)
A40: Return Bin (Midpoint) | B40: # Scenarios | C40: In Loss Tail? (< VaR) | F40: Monte Carlo (Normal) | G40: =C25 -> -29.833874 | K40: VaR Threshold (marker)
A41: -0.543989 | B41: 5 | C41: LOSS TAIL | F41: Parametric (Normal) | G41: =C21 -> -29.420714
A42: -0.501943 | B42: 12 | C42: LOSS TAIL | F42: Parametric (Student's t) | G42: =G28 -> -28.007031
...
